<?xml version='1.0' encoding='utf-8'?>
<robot name="complete_asm">
    <link name="wheel_leg_link">
        <inertial>
            <origin xyz="4.265785829993263e-05 -0.0005675946312863056 0.04816952028362232" rpy="0.0 -0.0 0.0" />
            <mass value="0.08795431472744088" />
            <inertia ixx="0.00014662929202897534" iyy="0.00010241588155809021" izz="5.942844770583619e-05" ixy="-1.3540006384949678e-06" iyz="9.39192671804035e-06" ixz="7.604128481846068e-07" />
        </inertial>
        <visual name="wheel_leg_link_visual">
            <origin xyz="-0.3199999999999368 -0.02800000000002727 0.08009999999999137" rpy="3.141592653589793 -0.0 0.0" />
            <geometry>
                <mesh filename="meshes/wheel_leg_link.stl" scale="0.001 0.001 0.001" />
            </geometry>
        </visual>
        <collision name="wheel_leg_link_collision">
            <origin xyz="-0.3199999999999368 -0.02800000000002727 0.08009999999999137" rpy="3.141592653589793 -0.0 0.0" />
            <geometry>
                <mesh filename="meshes/wheel_leg_link.stl" scale="0.001 0.001 0.001" />
            </geometry>
        </collision>
    </link>
    <link name="wheel_leg_link">
        <inertial>
            <origin xyz="-0.0039438957993081485 0.0005675946312863056 0.048007808927408024" rpy="0.0 -0.0 0.0" />
            <mass value="0.08795431472744088" />
            <inertia ixx="0.00014618004109328572" iyy="0.00010241588155808501" izz="5.987769864151881e-05" ixy="-5.888745102435906e-07" iyz="-9.470735558406724e-06" ixz="6.2889953252945855e-06" />
        </inertial>
        <visual name="wheel_leg_link_visual">
            <origin xyz="0.31246118649192794 0.028000000000027316 0.10575451692152703" rpy="-3.141592653589793 0.08108154571933589 -3.141592653589793" />
            <geometry>
                <mesh filename="meshes/wheel_leg_link.stl" scale="0.001 0.001 0.001" />
            </geometry>
        </visual>
        <collision name="wheel_leg_link_collision">
            <origin xyz="0.31246118649192794 0.028000000000027316 0.10575451692152703" rpy="-3.141592653589793 0.08108154571933589 -3.141592653589793" />
            <geometry>
                <mesh filename="meshes/wheel_leg_link.stl" scale="0.001 0.001 0.001" />
            </geometry>
        </collision>
    </link>
    <link name="wheel_leg_link">
        <inertial>
            <origin xyz="-0.003943902410563829 0.0005675946312863056 0.04800781564292761" rpy="0.0 -0.0 0.0" />
            <mass value="0.08795431472744088" />
            <inertia ixx="0.00014618004109328582" iyy="0.00010241588155808208" izz="5.987769864152315e-05" ixy="-5.888745102435719e-07" iyz="-9.470735558406751e-06" ixz="6.288995325294208e-06" />
        </inertial>
        <visual name="wheel_leg_link_visual">
            <origin xyz="0.3124611798806723 0.02800000000002731 0.1057545236370466" rpy="-3.141592653589793 0.08108154571933582 -3.141592653589793" />
            <geometry>
                <mesh filename="meshes/wheel_leg_link.stl" scale="0.001 0.001 0.001" />
            </geometry>
        </visual>
        <collision name="wheel_leg_link_collision">
            <origin xyz="0.3124611798806723 0.02800000000002731 0.1057545236370466" rpy="-3.141592653589793 0.08108154571933582 -3.141592653589793" />
            <geometry>
                <mesh filename="meshes/wheel_leg_link.stl" scale="0.001 0.001 0.001" />
            </geometry>
        </collision>
    </link>
    <link name="wheel_link">
        <inertial>
            <origin xyz="7.939551238678177e-10 5.492754862057581e-13 -0.014255053041864257" rpy="0.0 -0.0 0.0" />
            <mass value="0.05591773830133255" />
            <inertia ixx="4.406323757973962e-05" iyy="4.408143698717698e-05" izz="6.0539919163608586e-05" ixy="-9.85547610846367e-09" iyz="4.238768017737844e-16" ixz="-1.5737315447580317e-14" />
        </inertial>
        <visual name="wheel_link_visual">
            <origin xyz="0.31901445814319984 0.0007032000000086351 0.03221021342466946" rpy="1.5707963267948966 0.030044674202614665 3.141592653589793" />
            <geometry>
                <mesh filename="meshes/wheel_link.stl" scale="0.001 0.001 0.001" />
            </geometry>
        </visual>
        <collision name="wheel_link_collision">
            <origin xyz="0.31901445814319984 0.0007032000000086351 0.03221021342466946" rpy="1.5707963267948966 0.030044674202614665 3.141592653589793" />
            <geometry>
                <mesh filename="meshes/wheel_link.stl" scale="0.001 0.001 0.001" />
            </geometry>
        </collision>
    </link>
    <link name="wheel_link">
        <inertial>
            <origin xyz="0.159561270927275 0.011828367313113628 -0.01645963998285417" rpy="0.0 -0.0 0.0" />
            <mass value="0.05591773830133255" />
            <inertia ixx="4.406246959582195e-05" iyy="4.408222937774399e-05" izz="6.0539894756962435e-05" ixy="-9.085947531251642e-09" iyz="-2.003776325004276e-08" ixz="-4.176065140983335e-10" />
        </inertial>
        <visual name="wheel_link_visual">
            <origin xyz="0.4783411831563918 -0.0004492977957273231 0.029998577530843222" rpy="1.5695782601769546 0.03001998013625782 3.101033596186839" />
            <geometry>
                <mesh filename="meshes/wheel_link.stl" scale="0.001 0.001 0.001" />
            </geometry>
        </visual>
        <collision name="wheel_link_collision">
            <origin xyz="0.4783411831563918 -0.0004492977957273231 0.029998577530843222" rpy="1.5695782601769546 0.03001998013625782 3.101033596186839" />
            <geometry>
                <mesh filename="meshes/wheel_link.stl" scale="0.001 0.001 0.001" />
            </geometry>
        </collision>
    </link>
    <link name="wheel_link">
        <inertial>
            <origin xyz="0.31935765416141076 0.005343620366416893 -0.011657170249770398" rpy="0.0 -0.0 0.0" />
            <mass value="0.05591773830133255" />
            <inertia ixx="4.406246959582193e-05" iyy="4.408222937774605e-05" izz="6.0539894756962896e-05" ixy="-9.085947531212885e-09" iyz="-2.003776325004329e-08" ixz="-4.17606514285316e-10" />
        </inertial>
        <visual name="wheel_link_visual">
            <origin xyz="0.6381375663905275 -0.006934044742424035 0.034801047263926986" rpy="1.5695782601769546 0.030019980136257826 3.101033596186839" />
            <geometry>
                <mesh filename="meshes/wheel_link.stl" scale="0.001 0.001 0.001" />
            </geometry>
        </visual>
        <collision name="wheel_link_collision">
            <origin xyz="0.6381375663905275 -0.006934044742424035 0.034801047263926986" rpy="1.5695782601769546 0.030019980136257826 3.101033596186839" />
            <geometry>
                <mesh filename="meshes/wheel_link.stl" scale="0.001 0.001 0.001" />
            </geometry>
        </collision>
    </link>
    <link name="TOP_ARM_LINK미러">
        <inertial>
            <origin xyz="-0.03238526932608899 -0.01149964675436877 0.14093641386154013" rpy="0.0 -0.0 0.0" />
            <mass value="0.1912083481787344" />
            <inertia ixx="0.0001958985995300245" iyy="0.0010229852746595786" izz="0.0010352720955113855" ixy="-8.400436387674855e-05" iyz="2.0535171259301912e-05" ixz="-6.558845963348868e-05" />
        </inertial>
        <visual name="TOP_ARM_LINK미러_visual">
            <origin xyz="-0.22570419000000003 -0.11938531 -0.051427827378300074" rpy="1.5707963267948966 -0.0 0.0" />
            <geometry>
                <mesh filename="meshes/TOP_ARM_LINK미러.stl" scale="0.001 0.001 0.001" />
            </geometry>
        </visual>
        <collision name="TOP_ARM_LINK미러_collision">
            <origin xyz="-0.22570419000000003 -0.11938531 -0.051427827378300074" rpy="1.5707963267948966 -0.0 0.0" />
            <geometry>
                <mesh filename="meshes/TOP_ARM_LINK미러.stl" scale="0.001 0.001 0.001" />
            </geometry>
        </collision>
    </link>
    <link name="wheel_leg_link">
        <inertial>
            <origin xyz="4.265785830007474e-05 -0.0005675920095654874 0.04816952028362225" rpy="0.0 -0.0 0.0" />
            <mass value="0.08795431472744088" />
            <inertia ixx="0.00014662929202897707" iyy="0.00010241588155808674" izz="5.942844770583447e-05" ixy="-1.3540006384938838e-06" iyz="9.391926718040284e-06" ixz="7.60412848184607e-07" />
        </inertial>
        <visual name="wheel_leg_link_visual">
            <origin xyz="-0.31999999999993667 -0.02799999737830646 0.08009999999999129" rpy="3.141592653589793 -0.0 0.0" />
            <geometry>
                <mesh filename="meshes/wheel_leg_link.stl" scale="0.001 0.001 0.001" />
            </geometry>
        </visual>
        <collision name="wheel_leg_link_collision">
            <origin xyz="-0.31999999999993667 -0.02799999737830646 0.08009999999999129" rpy="3.141592653589793 -0.0 0.0" />
            <geometry>
                <mesh filename="meshes/wheel_leg_link.stl" scale="0.001 0.001 0.001" />
            </geometry>
        </collision>
    </link>
    <link name="wheel_leg_link">
        <inertial>
            <origin xyz="-4.2655205600965476e-05 0.000567592009565594 0.04816951538702037" rpy="0.0 -0.0 0.0" />
            <mass value="0.08795431472744088" />
            <inertia ixx="0.00014662929202897558" iyy="0.00010241588155808371" izz="5.942844770583338e-05" ixy="-1.3540006384947338e-06" iyz="-9.391926718040338e-06" ixz="-7.60412848184164e-07" />
        </inertial>
        <visual name="wheel_leg_link_visual">
            <origin xyz="0.3200000026526359 0.02799999737830653 0.08009999510338954" rpy="3.141592653589793 3.816391647148974e-16 3.141592653589793" />
            <geometry>
                <mesh filename="meshes/wheel_leg_link.stl" scale="0.001 0.001 0.001" />
            </geometry>
        </visual>
        <collision name="wheel_leg_link_collision">
            <origin xyz="0.3200000026526359 0.02799999737830653 0.08009999510338954" rpy="3.141592653589793 3.816391647148974e-16 3.141592653589793" />
            <geometry>
                <mesh filename="meshes/wheel_leg_link.stl" scale="0.001 0.001 0.001" />
            </geometry>
        </collision>
    </link>
    <link name="wheel_leg_link">
        <inertial>
            <origin xyz="-4.2661251228348905e-05 0.0005675920095654874 0.04816952261593439" rpy="0.0 -0.0 0.0" />
            <mass value="0.08795431472744088" />
            <inertia ixx="0.00014662929202897642" iyy="0.00010241588155808181" izz="5.942844770583167e-05" ixy="-1.3540006384957502e-06" iyz="-9.391926718040187e-06" ixz="-7.604128481845672e-07" />
        </inertial>
        <visual name="wheel_leg_link_visual">
            <origin xyz="0.3199999966070085 0.027999997378306427 0.08010000233230344" rpy="3.141592653589793 1.3877787807814454e-17 3.141592653589793" />
            <geometry>
                <mesh filename="meshes/wheel_leg_link.stl" scale="0.001 0.001 0.001" />
            </geometry>
        </visual>
        <collision name="wheel_leg_link_collision">
            <origin xyz="0.3199999966070085 0.027999997378306427 0.08010000233230344" rpy="3.141592653589793 1.3877787807814454e-17 3.141592653589793" />
            <geometry>
                <mesh filename="meshes/wheel_leg_link.stl" scale="0.001 0.001 0.001" />
            </geometry>
        </collision>
    </link>
    <link name="wheel_link">
        <inertial>
            <origin xyz="-0.007329808509846742 5.493465404793341e-13 0.2226352788982497" rpy="0.0 -0.0 0.0" />
            <mass value="0.05591773830133255" />
            <inertia ixx="4.406323757973976e-05" iyy="4.4081436987185654e-05" izz="6.0539919163610314e-05" ixy="-9.855476108463676e-09" iyz="4.2387701342862363e-16" ixz="-1.573747214867556e-14" />
        </inertial>
        <visual name="wheel_link_visual">
            <origin xyz="0.3116846488393979 0.0007032000000087063 0.2691005453647834" rpy="1.5707963267948966 0.030044674202614665 3.141592653589793" />
            <geometry>
                <mesh filename="meshes/wheel_link.stl" scale="0.001 0.001 0.001" />
            </geometry>
        </visual>
        <collision name="wheel_link_collision">
            <origin xyz="0.3116846488393979 0.0007032000000087063 0.2691005453647834" rpy="1.5707963267948966 0.030044674202614665 3.141592653589793" />
            <geometry>
                <mesh filename="meshes/wheel_link.stl" scale="0.001 0.001 0.001" />
            </geometry>
        </collision>
    </link>
    <link name="wheel_link">
        <inertial>
            <origin xyz="0.15223145984528189 0.011828367313107005 0.2274306882187838" rpy="0.0 -0.0 0.0" />
            <mass value="0.05591773830133255" />
            <inertia ixx="4.406246959582195e-05" iyy="4.4082229377745506e-05" izz="6.0539894756961113e-05" ixy="-9.085947531172095e-09" iyz="-2.0037763249982747e-08" ixz="-4.1760651449305084e-10" />
        </inertial>
        <visual name="wheel_link_visual">
            <origin xyz="0.47101137207439875 -0.0004492977957340533 0.27388890573248115" rpy="1.5695782601769546 0.030019980136257632 3.1010335961868387" />
            <geometry>
                <mesh filename="meshes/wheel_link.stl" scale="0.001 0.001 0.001" />
            </geometry>
        </visual>
        <collision name="wheel_link_collision">
            <origin xyz="0.47101137207439875 -0.0004492977957340533 0.27388890573248115" rpy="1.5695782601769546 0.030019980136257632 3.1010335961868387" />
            <geometry>
                <mesh filename="meshes/wheel_link.stl" scale="0.001 0.001 0.001" />
            </geometry>
        </collision>
    </link>
    <link name="wheel_link">
        <inertial>
            <origin xyz="0.31202784367958775 0.0053436203351600025 0.23223316363356403" rpy="0.0 -0.0 0.0" />
            <mass value="0.05591773830133255" />
            <inertia ixx="4.4062469595821964e-05" iyy="4.408222937774377e-05" izz="6.0539894756961466e-05" ixy="-9.085947531323923e-09" iyz="-2.0037763250041543e-08" ixz="-4.176065148121705e-10" />
        </inertial>
        <visual name="wheel_link_visual">
            <origin xyz="0.6308077559087045 -0.0069340447736809365 0.2786913811472614" rpy="1.5695782601769546 0.030019980136257576 3.101033596186839" />
            <geometry>
                <mesh filename="meshes/wheel_link.stl" scale="0.001 0.001 0.001" />
            </geometry>
        </visual>
        <collision name="wheel_link_collision">
            <origin xyz="0.6308077559087045 -0.0069340447736809365 0.2786913811472614" rpy="1.5695782601769546 0.030019980136257576 3.101033596186839" />
            <geometry>
                <mesh filename="meshes/wheel_link.stl" scale="0.001 0.001 0.001" />
            </geometry>
        </collision>
    </link>
    <link name="TOP_ARM_LINK">
        <inertial>
            <origin xyz="-0.032385258019524875 0.01149965023114376 0.14093640770644614" rpy="0.0 -0.0 0.0" />
            <mass value="0.19120862158222582" />
            <inertia ixx="0.00019589866005841576" iyy="0.001022986054145625" izz="0.0010352728891539018" ixy="8.400448212675466e-05" iyz="-2.0535171437438372e-05" ixz="-6.558845825931253e-05" />
        </inertial>
        <visual name="TOP_ARM_LINK_visual">
            <origin xyz="-0.22570419000000003 0.11938531 -0.05142783" rpy="1.5707963267948966 -0.0 0.0" />
            <geometry>
                <mesh filename="meshes/TOP_ARM_LINK.stl" scale="0.001 0.001 0.001" />
            </geometry>
        </visual>
        <collision name="TOP_ARM_LINK_collision">
            <origin xyz="-0.22570419000000003 0.11938531 -0.05142783" rpy="1.5707963267948966 -0.0 0.0" />
            <geometry>
                <mesh filename="meshes/TOP_ARM_LINK.stl" scale="0.001 0.001 0.001" />
            </geometry>
        </collision>
    </link>
    <link name="LOWER_ARM_LINK">
        <inertial>
            <origin xyz="-0.0002667807203070538 -0.006576617976634101 0.013926693085337546" rpy="0.0 -0.0 0.0" />
            <mass value="0.07644747488590392" />
            <inertia ixx="1.518872835581074e-05" iyy="0.0001608350921559823" izz="0.0001658011017489962" ixy="5.917637974289639e-06" iyz="3.997600047608331e-07" ixz="1.6058426582617538e-08" />
        </inertial>
        <visual name="LOWER_ARM_LINK_visual">
            <origin xyz="-0.0776846 0.07551962 -0.20200045" rpy="1.5707963267948966 -0.0 0.0" />
            <geometry>
                <mesh filename="meshes/LOWER_ARM_LINK.stl" scale="0.001 0.001 0.001" />
            </geometry>
        </visual>
        <collision name="LOWER_ARM_LINK_collision">
            <origin xyz="-0.0776846 0.07551962 -0.20200045" rpy="1.5707963267948966 -0.0 0.0" />
            <geometry>
                <mesh filename="meshes/LOWER_ARM_LINK.stl" scale="0.001 0.001 0.001" />
            </geometry>
        </collision>
    </link>
    <link name="LOWER_ARM_LINK미러">
        <inertial>
            <origin xyz="-0.0002667807203070982 0.0065766179766340565 0.013926695707037511" rpy="0.0 -0.0 0.0" />
            <mass value="0.07644747488590391" />
            <inertia ixx="1.518872835580846e-05" iyy="0.00016083509215597855" izz="0.00016580110174899642" ixy="-5.917637974289475e-06" iyz="-3.9976000476042646e-07" ixz="1.6058426582888585e-08" />
        </inertial>
        <visual name="LOWER_ARM_LINK미러_visual">
            <origin xyz="-0.0776846 -0.07551962000000001 -0.20200044737830006" rpy="1.5707963267948966 -0.0 0.0" />
            <geometry>
                <mesh filename="meshes/LOWER_ARM_LINK미러.stl" scale="0.001 0.001 0.001" />
            </geometry>
        </visual>
        <collision name="LOWER_ARM_LINK미러_collision">
            <origin xyz="-0.0776846 -0.07551962000000001 -0.20200044737830006" rpy="1.5707963267948966 -0.0 0.0" />
            <geometry>
                <mesh filename="meshes/LOWER_ARM_LINK미러.stl" scale="0.001 0.001 0.001" />
            </geometry>
        </collision>
    </link>
    <link name="LARGE_BEVEL_GEAR_LINK">
        <inertial>
            <origin xyz="-0.0004180989205912944 -1.977490234494894e-05 -0.003986928564440113" rpy="0.0 -0.0 0.0" />
            <mass value="0.028432436502394933" />
            <inertia ixx="2.256122504881912e-05" iyy="2.659425682503911e-06" izz="2.4911127286641286e-05" ixy="9.434639437506393e-07" iyz="-2.552451845737599e-11" ixz="-5.288493850960906e-10" />
        </inertial>
        <visual name="LARGE_BEVEL_GEAR_LINK_visual">
            <origin xyz="0.14997835172025495 -0.0941 -0.23233769271935537" rpy="3.141592653589793 -1.42882689753879 3.141592653589793" />
            <geometry>
                <mesh filename="meshes/LARGE_BEVEL_GEAR_LINK.stl" scale="0.001 0.001 0.001" />
            </geometry>
        </visual>
        <collision name="LARGE_BEVEL_GEAR_LINK_collision">
            <origin xyz="0.14997835172025495 -0.0941 -0.23233769271935537" rpy="3.141592653589793 -1.42882689753879 3.141592653589793" />
            <geometry>
                <mesh filename="meshes/LARGE_BEVEL_GEAR_LINK.stl" scale="0.001 0.001 0.001" />
            </geometry>
        </collision>
    </link>
    <link name="BODY_LINK">
        <inertial>
            <origin xyz="0.16624116391034044 0.09396654441652777 0.11779752612733436" rpy="0.0 0.0 0.0" />
            <mass value="0.6138005117468571" />
            <inertia ixx="0.0022712909585396995" iyy="0.0037692109401669567" izz="0.004694617476945499" ixy="-1.6967718847130803e-06" iyz="8.494760985883199e-07" ixz="0.00022740405945444707" />
        </inertial>
        <visual name="BODY_LINK_visual">
            <origin xyz="0.0 0.0 0.0" rpy="0.0 0.0 0.0" />
            <geometry>
                <mesh filename="meshes/BODY_LINK.stl" scale="0.001 0.001 0.001" />
            </geometry>
        </visual>
        <collision name="BODY_LINK_collision">
            <origin xyz="0.0 0.0 0.0" rpy="0.0 0.0 0.0" />
            <geometry>
                <mesh filename="meshes/BODY_LINK.stl" scale="0.001 0.001 0.001" />
            </geometry>
        </collision>
    </link>
    <joint name="wheel_leg_link_회전-1" type="continuous">
        <origin xyz="-0.00015771000000000868 -0.005247629999999996 0.0808032" rpy="-1.5707963267948966 -0.0 3.1115479793871788" />
        <parent link="wheel_leg_link" />
        <child link="wheel_link" />
        <axis xyz="-1.634341986883614e-07 0.0 1.000000302500441" />
    </joint>
    <joint name="wheel_leg_link_회전-2" type="continuous">
        <origin xyz="-0.1661501764032297 0.01249438 0.08589107206261985" rpy="-1.5695778086865493 -0.0405224664905253 -0.0300693662642092" />
        <parent link="wheel_leg_link" />
        <child link="wheel_link" />
        <axis xyz="-2.5152151516851656e-05 -0.001218 0.999999551496584" />
    </joint>
    <joint name="wheel_leg_link_회전-3" type="continuous">
        <origin xyz="-0.32562453372237926 0.012494359999999998 0.07293224139610428" rpy="-1.5695778086865493 -0.0405224664905253 -0.0300693662642092" />
        <parent link="wheel_leg_link" />
        <child link="wheel_link" />
        <axis xyz="-2.5152151516851656e-05 -0.001218 0.999999551496584" />
    </joint>
    <joint name="wheel_leg_link_회전-4" type="continuous">
        <origin xyz="-0.0003754999999999953 0.23150607 0.0808032" rpy="-1.5707963267948966 -0.0 3.1115479793871788" />
        <parent link="wheel_leg_link" />
        <child link="wheel_link" />
        <axis xyz="-1.634341986883614e-07 0.0 1.000000302500441" />
    </joint>
    <joint name="wheel_leg_link_회전-5" type="continuous">
        <origin xyz="-0.1586477691654984 -0.23150607 0.09906585041123527" rpy="-1.572014844903244 0.04052246649052531 -0.030069366264209203" />
        <parent link="wheel_leg_link" />
        <child link="wheel_link" />
        <axis xyz="-2.5152151516851656e-05 -0.001218 0.999999551496584" />
    </joint>
    <joint name="wheel_leg_link_회전-6" type="continuous">
        <origin xyz="-0.31864777521112064 -0.23150607 0.09906585764015598" rpy="-1.572014844903244 0.04052246649052531 -0.030069366264209203" />
        <parent link="wheel_leg_link" />
        <child link="wheel_link" />
        <axis xyz="-2.5152151516851656e-05 -0.001218 0.999999551496584" />
    </joint>
    <joint name="TOP_ARM_LINK_회전-7" type="continuous">
        <origin xyz="0.09429581 0.03938530999999999 0.16457262" rpy="-1.5707963267948966 -0.0 0.0" />
        <parent link="TOP_ARM_LINK" />
        <child link="wheel_leg_link" />
        <axis xyz="0.0 0.0 1.0" />
    </joint>
    <joint name="LOWER_ARM_LINK_회전-8" type="continuous">
        <origin xyz="0.07940738000000001 -0.016231690000000007 0.014000000000000021" rpy="1.5707963267948966 -0.0 3.1010518807301253" />
        <parent link="LOWER_ARM_LINK" />
        <child link="wheel_leg_link" />
        <axis xyz="-3.447097470174465e-07 0.0 0.999999678291889" />
    </joint>
    <joint name="LOWER_ARM_LINK_회전-9" type="continuous">
        <origin xyz="-0.08046116 -0.009746950000000006 0.014000000000000021" rpy="1.5707963267948966 -0.0 3.1010518807301253" />
        <parent link="LOWER_ARM_LINK" />
        <child link="wheel_leg_link" />
        <axis xyz="-3.447097470174465e-07 0.0 0.999999678291889" />
    </joint>
    <joint name="TOP_ARM_LINK미러_회전-10" type="continuous">
        <origin xyz="0.09429581 -0.03938530999999999 0.16457262" rpy="1.5707963267948966 -0.0 0.0" />
        <parent link="TOP_ARM_LINK미러" />
        <child link="wheel_leg_link" />
        <axis xyz="0.0 0.0 -0.9999999999999999" />
    </joint>
    <joint name="LOWER_ARM_LINK미러_회전-11" type="continuous">
        <origin xyz="0.07940738 0.01623169 0.013999999999999999" rpy="-1.5707963267948966 -0.0 3.1010518807301253" />
        <parent link="LOWER_ARM_LINK미러" />
        <child link="wheel_leg_link" />
        <axis xyz="0.08099305115897235 0.0 -0.9967143433541829" />
    </joint>
    <joint name="LOWER_ARM_LINK미러_회전-13" type="continuous">
        <origin xyz="-0.08046116000000002 0.009746949999999997 0.013999999999999999" rpy="-1.5707963267948966 -0.0 3.1010518807301253" />
        <parent link="LOWER_ARM_LINK미러" />
        <child link="wheel_leg_link" />
        <axis xyz="0.08099305115897235 0.0 -0.9967143433541829" />
    </joint>
    <joint name="TOP_ARM_LINK미러_회전-14" type="continuous">
        <origin xyz="-0.14801959 -0.04386569 0.15057262" rpy="0.0 -0.0 0.0" />
        <parent link="TOP_ARM_LINK미러" />
        <child link="LOWER_ARM_LINK미러" />
        <axis xyz="0.0 0.0 -1.0" />
    </joint>
    <joint name="TOP_ARM_LINK_회전-15" type="continuous">
        <origin xyz="-0.14801959 0.04386569 0.15057262" rpy="0.0 -0.0 0.0" />
        <parent link="TOP_ARM_LINK" />
        <child link="LOWER_ARM_LINK" />
        <axis xyz="0.0 0.0 1.0" />
    </joint>
    <joint name="TOP_ARM_LINK미러_회전-16" type="continuous">
        <origin xyz="0.0 0.0 0.08514479" rpy="3.141592653589793 -0.0 0.0" />
        <parent link="TOP_ARM_LINK미러" />
        <child link="TOP_ARM_LINK" />
        <axis xyz="0.0 0.0 -1.0" />
    </joint>
    <joint name="TOP_ARM_LINK_회전-17" type="continuous">
        <origin xyz="0.0 0.0 0.08514479" rpy="3.141592653589793 -0.0 0.0" />
        <parent link="TOP_ARM_LINK" />
        <child link="TOP_ARM_LINK미러" />
        <axis xyz="0.0 0.0 1.0" />
    </joint>
    <joint name="BODY_LINK_회전-18" type="revolute">
        <origin xyz="0.25122109 0.0941 0.11559530000000001" rpy="3.141592653589793 1.42882689753879 3.141592653589793" />
        <parent link="BODY_LINK" />
        <child link="LARGE_BEVEL_GEAR_LINK" />
        <axis xyz="3.310086940655488e-08 0.0 0.9999997463849672" />
        <limit lower="-0.523599" upper="0.523599" effort="1000000" velocity="1000000" />
    </joint>
</robot>